Workbook

Sheet FARM_DATA
A1: Date | B1: Farmer_Type | C1: Income | D1: Irrigation | E1: Seeds | F1: Fertilizer | G1: Labor | H1: Household | I1: Medical | J1: Misc | K1: Total_Expenses | L1: Savings
A2: 45383 | B2: Traditional | C2: 374.84 | D2: 68.62 | E2: 49.72 | F2: 85.46 | G2: 104.15 | H2: 142.98 | I2: 32.63 | J2: 39.21 | K2: 522.76 | L2: -147.92
A3: 45384 | B3: Smart | C3: 856.11 | D3: 17.71 | E3: 50.73 | F3: 66.03 | G3: 99.84 | H3: 103.04 | I3: 6.48 | J3: 31.57 | K3: 375.39 | L3: 480.72
A4: 45385 | B4: Traditional | C4: 299.36 | D4: 73.14 | E4: 26.38 | F4: 26.75 | G4: 146.64 | H4: 143.23 | I4: 20.54 | J4: 12.9 | K4: 449.59 | L4: -150.23
A5: 45386 | B5: Smart | C5: 841.12 | D5: 15.55 | E5: 36.98 | F5: 91.27 | G5: 82.99 | H5: 159.79 | I5: 16.58 | J5: 67.78 | K5: 470.95 | L5: 370.17
A6: 45387 | B6: Traditional | C6: 349.33 | D6: 59.42 | E6: 52.34 | F6: 30.58 | G6: 115.22 | H6: 91.21 | I6: 9.37 | J6: 32.36 | K6: 390.51 | L6: -41.19
A7: 45388 | B7: Smart | C7: 1097.69 | D7: 15.86 | E7: 57.69 | F7: 70.97 | G7: 65.43 | H7: 144.81 | I7: 17.85 | J7: 55.86 | K7: 428.46 | L7: 669.24
A8: 45389 | B8: Smart | C8: 1018.72 | D8: 6.18 | E8: 66.48 | F8: 68.45 | G8: 81.46 | H8: 191.41 | I8: 31.28 | J8: 53.97 | K8: 499.23 | L8: 519.49
A9: 45390 | B9: Traditional | C9: 308.04 | D9: 66.91 | E9: 44.97 | F9: 74.51 | G9: 98.02 | H9: 144.43 | I9: 11.15 | J9: 15.65 | K9: 455.63 | L9: -147.59
A10: 45391 | B10: Traditional | C10: 390.63 | D10: 83.56 | E10: 38.92 | F10: 75.07 | G10: 119.04 | H10: 130.65 | I10: 22.89 | J10: 48.46 | K10: 518.59 | L10: -127.96
A11: 45392 | B11: Traditional | C11: 348.21 | D11: 85.65 | E11: 0.7 | F11: 71.44 | G11: 112.18 | H11: 141.03 | I11: 20.73 | J11: 6.15 | K11: 437.88 | L11: -89.67
A12: 45393 | B12: Smart | C12: 906.07 | D12: 16.79 | E12: 89.56 | F12: 64.45 | G12: 78.83 | H12: 152.44 | I12: 30.24 | J12: 44.93 | K12: 477.23 | L12: 428.83
A13: 45394 | B13: Smart | C13: 844.05 | D13: 17.57 | E13: 61.94 | F13: 109.06 | G13: 80.96 | H13: 158.53 | I13: 18.47 | J13: 18.05 | K13: 464.58 | L13: 379.47
... A366: 45747 | B366: Traditional | C366: 313.45 | D366: 77.58 | E366: 50.28 | F366: 91.97 | G366: 105.61 | H366: 170.06 | I366: 20.78 | J366: 45.55 | K366: 561.84 | L366: -248.39

Sheet CLEAN_DATA
A1: Date | B1: Farmer_Type | C1: Income | D1: Irrigation | E1: Seeds | F1: Fertilizer | G1: Labour | H1: Household | I1: Medical | J1: Misc | K1: TotalExpenses | L1: Savings | M1: Month | N1: Year | O1: Farmer_Category_ID | P1: Savings_Rate | Q1: Irrigation_Efficiency | R1: Daily_Risk_Score | S1: Expense_Total
A2: =FARM_DATA[[#This Row],[Date]] -> 45383 | B2: =FARM_DATA[[#This Row],[Farmer_Type]] -> Traditional | C2: =FARM_DATA[[#This Row],[Income]] -> 374.84 | D2: =FARM_DATA[[#This Row],[Irrigation]] -> 68.62 | E2: =FARM_DATA[[#This Row],[Seeds]] -> 49.72 | F2: =FARM_DATA[[#This Row],[Fertilizer]] -> 85.46 | G2: =FARM_DATA[[#This Row],[Labor]] -> 104.15 | H2: =FARM_DATA[[#This Row],[Household]] -> 142.98 | I2: =FARM_DATA[[#This Row],[Medical]] -> 32.63 | J2: =FARM_DATA[[#This Row],[Misc]] -> 39.21 | K2: =FARM_DATA[[#This Row],[Total_Expenses]] -> 522.76 | L2: =FARM_DATA[[#This Row],[Savings]] -> -147.92 | M2: =TEXT(CLEAN_TABLE[[#This Row],[Date]], "mmm") -> Apr | N2: =YEAR(CLEAN_TABLE[[#This Row],[Date]]) -> 2024 | O2: =IF(CLEAN_TABLE[[#This Row],[Farmer_Type]]="Smart",0,1) -> 1 | P2: =IFERROR(CLEAN_TABLE[[#This Row],[Savings]]/CLEAN_TABLE[[#This Row],[Income]],0) -> -0.39462171 | Q2: =IF(CLEAN_TABLE[[#This Row],[Farmer_Type]]="Smart", 1 - (CLEAN_TABLE[[#This Row],[Irrigation]] / 70), 1 - (CLEAN_TABLE[[#This Row],[Irrigation]] / 150)) -> 0.54253333 | R2: =_xlfn.LET( _xlpm.income,CLEAN_TABLE[[#This Row],[Income]], _xlpm.expense,CLEAN_TABLE[[#This Row],[TotalExpenses]], _xlpm.saving,CLEAN_TABLE[[#This Row],[Savings]], IF(_xlpm.saving < 0, 20, IF(_xlpm.saving/_xlpm.income < 0.1, 40, IF(_xlpm.saving/_xlpm.income < 0.2, 60, 80)))) -> 20 | S2: =CLEAN_TABLE[[#This Row],[Income]]+CLEAN_TABLE[[#This Row],[Irrigation]]+CLEAN_TABLE[[#This Row],[Seeds ]]+CLEAN_TABLE[[#This Row],[Fertilizer]]+CLEAN_TABLE[[#This Row],[Labour ]]+CLEAN_TABLE[[#This Row],[Household]]+CLEAN_TABLE[[#This Row],[Medical ]]+CLEAN_TABLE[[#This Row],[Misc]] -> 897.61
A3: =FARM_DATA[[#This Row],[Date]] -> 45384 | B3: =FARM_DATA[[#This Row],[Farmer_Type]] -> Smart | C3: =FARM_DATA[[#This Row],[Income]] -> 856.11 | D3: =FARM_DATA[[#This Row],[Irrigation]] -> 17.71 | E3: =FARM_DATA[[#This Row],[Seeds]] -> 50.73 | F3: =FARM_DATA[[#This Row],[Fertilizer]] -> 66.03 | G3: =FARM_DATA[[#This Row],[Labor]] -> 99.84 | H3: =FARM_DATA[[#This Row],[Household]] -> 103.04 | I3: =FARM_DATA[[#This Row],[Medical]] -> 6.48 | J3: =FARM_DATA[[#This Row],[Misc]] -> 31.57 | K3: =FARM_DATA[[#This Row],[Total_Expenses]] -> 375.39 | L3: =FARM_DATA[[#This Row],[Savings]] -> 480.72 | M3: =TEXT(CLEAN_TABLE[[#This Row],[Date]], "mmm") -> Apr | N3: =YEAR(CLEAN_TABLE[[#This Row],[Date]]) -> 2024 | O3: =IF(CLEAN_TABLE[[#This Row],[Farmer_Type]]="Smart",0,1) -> 0 | P3: =IFERROR(CLEAN_TABLE[[#This Row],[Savings]]/CLEAN_TABLE[[#This Row],[Income]],0) -> 0.56151663 | Q3: =IF(CLEAN_TABLE[[#This Row],[Farmer_Type]]="Smart", 1 - (CLEAN_TABLE[[#This Row],[Irrigation]] / 70), 1 - (CLEAN_TABLE[[#This Row],[Irrigation]] / 150)) -> 0.747 | R3: =_xlfn.LET( _xlpm.income,CLEAN_TABLE[[#This Row],[Income]], _xlpm.expense,CLEAN_TABLE[[#This Row],[TotalExpenses]], _xlpm.saving,CLEAN_TABLE[[#This Row],[Savings]], IF(_xlpm.saving < 0, 20, IF(_xlpm.saving/_xlpm.income < 0.1, 40, IF(_xlpm.saving/_xlpm.income < 0.2, 60, 80)))) -> 80 | S3: =CLEAN_TABLE[[#This Row],[Income]]+CLEAN_TABLE[[#This Row],[Irrigation]]+CLEAN_TABLE[[#This Row],[Seeds ]]+CLEAN_TABLE[[#This Row],[Fertilizer]]+CLEAN_TABLE[[#This Row],[Labour ]]+CLEAN_TABLE[[#This Row],[Household]]+CLEAN_TABLE[[#This Row],[Medical ]]+CLEAN_TABLE[[#This Row],[Misc]] -> 1231.51
A4: =FARM_DATA[[#This Row],[Date]] -> 45385 | B4: =FARM_DATA[[#This Row],[Farmer_Type]] -> Traditional | C4: =FARM_DATA[[#This Row],[Income]] -> 299.36 | D4: =FARM_DATA[[#This Row],[Irrigation]] -> 73.14 | E4: =FARM_DATA[[#This Row],[Seeds]] -> 26.38 | F4: =FARM_DATA[[#This Row],[Fertilizer]] -> 26.75 | G4: =FARM_DATA[[#This Row],[Labor]] -> 146.64 | H4: =FARM_DATA[[#This Row],[Household]] -> 143.23 | I4: =FARM_DATA[[#This Row],[Medical]] -> 20.54 | J4: =FARM_DATA[[#This Row],[Misc]] -> 12.9 | K4: =FARM_DATA[[#This Row],[Total_Expenses]] -> 449.59 | L4: =FARM_DATA[[#This Row],[Savings]] -> -150.23 | M4: =TEXT(CLEAN_TABLE[[#This Row],[Date]], "mmm") -> Apr | N4: =YEAR(CLEAN_TABLE[[#This Row],[Date]]) -> 2024 | O4: =IF(CLEAN_TABLE[[#This Row],[Farmer_Type]]="Smart",0,1) -> 1 | P4: =IFERROR(CLEAN_TABLE[[#This Row],[Savings]]/CLEAN_TABLE[[#This Row],[Income]],0) -> -0.50183725 | Q4: =IF(CLEAN_TABLE[[#This Row],[Farmer_Type]]="Smart", 1 - (CLEAN_TABLE[[#This Row],[Irrigation]] / 70), 1 - (CLEAN_TABLE[[#This Row],[Irrigation]] / 150)) -> 0.5124 | R4: =_xlfn.LET( _xlpm.income,CLEAN_TABLE[[#This Row],[Income]], _xlpm.expense,CLEAN_TABLE[[#This Row],[TotalExpenses]], _xlpm.saving,CLEAN_TABLE[[#This Row],[Savings]], IF(_xlpm.saving < 0, 20, IF(_xlpm.saving/_xlpm.income < 0.1, 40, IF(_xlpm.saving/_xlpm.income < 0.2, 60, 80)))) -> 20 | S4: =CLEAN_TABLE[[#This Row],[Income]]+CLEAN_TABLE[[#This Row],[Irrigation]]+CLEAN_TABLE[[#This Row],[Seeds ]]+CLEAN_TABLE[[#This Row],[Fertilizer]]+CLEAN_TABLE[[#This Row],[Labour ]]+CLEAN_TABLE[[#This Row],[Household]]+CLEAN_TABLE[[#This Row],[Medical ]]+CLEAN_TABLE[[#This Row],[Misc]] -> 748.94
A5: =FARM_DATA[[#This Row],[Date]] -> 45386 | B5: =FARM_DATA[[#This Row],[Farmer_Type]] -> Smart | C5: =FARM_DATA[[#This Row],[Income]] -> 841.12 | D5: =FARM_DATA[[#This Row],[Irrigation]] -> 15.55 | E5: =FARM_DATA[[#This Row],[Seeds]] -> 36.98 | F5: =FARM_DATA[[#This Row],[Fertilizer]] -> 91.27 | G5: =FARM_DATA[[#This Row],[Labor]] -> 82.99 | H5: =FARM_DATA[[#This Row],[Household]] -> 159.79 | I5: =FARM_DATA[[#This Row],[Medical]] -> 16.58 | J5: =FARM_DATA[[#This Row],[Misc]] -> 67.78 | K5: =FARM_DATA[[#This Row],[Total_Expenses]] -> 470.95 | L5: =FARM_DATA[[#This Row],[Savings]] -> 370.17 | M5: =TEXT(CLEAN_TABLE[[#This Row],[Date]], "mmm") -> Apr | N5: =YEAR(CLEAN_TABLE[[#This Row],[Date]]) -> 2024 | O5: =IF(CLEAN_TABLE[[#This Row],[Farmer_Type]]="Smart",0,1) -> 0 | P5: =IFERROR(CLEAN_TABLE[[#This Row],[Savings]]/CLEAN_TABLE[[#This Row],[Income]],0) -> 0.44009178 | Q5: =IF(CLEAN_TABLE[[#This Row],[Farmer_Type]]="Smart", 1 - (CLEAN_TABLE[[#This Row],[Irrigation]] / 70), 1 - (CLEAN_TABLE[[#This Row],[Irrigation]] / 150)) -> 0.77785714 | R5: =_xlfn.LET( _xlpm.income,CLEAN_TABLE[[#This Row],[Income]], _xlpm.expense,CLEAN_TABLE[[#This Row],[TotalExpenses]], _xlpm.saving,CLEAN_TABLE[[#This Row],[Savings]], IF(_xlpm.saving < 0, 20, IF(_xlpm.saving/_xlpm.income < 0.1, 40, IF(_xlpm.saving/_xlpm.income < 0.2, 60, 80)))) -> 80 | S5: =CLEAN_TABLE[[#This Row],[Income]]+CLEAN_TABLE[[#This Row],[Irrigation]]+CLEAN_TABLE[[#This Row],[Seeds ]]+CLEAN_TABLE[[#This Row],[Fertilizer]]+CLEAN_TABLE[[#This Row],[Labour ]]+CLEAN_TABLE[[#This Row],[Household]]+CLEAN_TABLE[[#This Row],[Medical ]]+CLEAN_TABLE[[#This Row],[Misc]] -> 1312.06
A6: =FARM_DATA[[#This Row],[Date]] -> 45387 | B6: =FARM_DATA[[#This Row],[Farmer_Type]] -> Traditional | C6: =FARM_DATA[[#This Row],[Income]] -> 349.33 | D6: =FARM_DATA[[#This Row],[Irrigation]] -> 59.42 | E6: =FARM_DATA[[#This Row],[Seeds]] -> 52.34 | F6: =FARM_DATA[[#This Row],[Fertilizer]] -> 30.58 | G6: =FARM_DATA[[#This Row],[Labor]] -> 115.22 | H6: =FARM_DATA[[#This Row],[Household]] -> 91.21 | I6: =FARM_DATA[[#This Row],[Medical]] -> 9.37 | J6: =FARM_DATA[[#This Row],[Misc]] -> 32.36 | K6: =FARM_DATA[[#This Row],[Total_Expenses]] -> 390.51 | L6: =FARM_DATA[[#This Row],[Savings]] -> -41.19 | M6: =TEXT(CLEAN_TABLE[[#This Row],[Date]], "mmm") -> Apr | N6: =YEAR(CLEAN_TABLE[[#This Row],[Date]]) -> 2024 | O6: =IF(CLEAN_TABLE[[#This Row],[Farmer_Type]]="Smart",0,1) -> 1 | P6: =IFERROR(CLEAN_TABLE[[#This Row],[Savings]]/CLEAN_TABLE[[#This Row],[Income]],0) -> -0.11791143 | Q6: =IF(CLEAN_TABLE[[#This Row],[Farmer_Type]]="Smart", 1 - (CLEAN_TABLE[[#This Row],[Irrigation]] / 70), 1 - (CLEAN_TABLE[[#This Row],[Irrigation]] / 150)) -> 0.60386667 | R6: =_xlfn.LET( _xlpm.income,CLEAN_TABLE[[#This Row],[Income]], _xlpm.expense,CLEAN_TABLE[[#This Row],[TotalExpenses]], _xlpm.saving,CLEAN_TABLE[[#This Row],[Savings]], IF(_xlpm.saving < 0, 20, IF(_xlpm.saving/_xlpm.income < 0.1, 40, IF(_xlpm.saving/_xlpm.income < 0.2, 60, 80)))) -> 20 | S6: =CLEAN_TABLE[[#This Row],[Income]]+CLEAN_TABLE[[#This Row],[Irrigation]]+CLEAN_TABLE[[#This Row],[Seeds ]]+CLEAN_TABLE[[#This Row],[Fertilizer]]+CLEAN_TABLE[[#This Row],[Labour ]]+CLEAN_TABLE[[#This Row],[Household]]+CLEAN_TABLE[[#This Row],[Medical ]]+CLEAN_TABLE[[#This Row],[Misc]] -> 739.83
A7: =FARM_DATA[[#This Row],[Date]] -> 45388 | B7: =FARM_DATA[[#This Row],[Farmer_Type]] -> Smart | C7: =FARM_DATA[[#This Row],[Income]] -> 1097.69 | D7: =FARM_DATA[[#This Row],[Irrigation]] -> 15.86 | E7: =FARM_DATA[[#This Row],[Seeds]] -> 57.69 | F7: =FARM_DATA[[#This Row],[Fertilizer]] -> 70.97 | G7: =FARM_DATA[[#This Row],[Labor]] -> 65.43 | H7: =FARM_DATA[[#This Row],[Household]] -> 144.81 | I7: =FARM_DATA[[#This Row],[Medical]] -> 17.85 | J7: =FARM_DATA[[#This Row],[Misc]] -> 55.86 | K7: =FARM_DATA[[#This Row],[Total_Expenses]] -> 428.46 | L7: =FARM_DATA[[#This Row],[Savings]] -> 669.24 | M7: =TEXT(CLEAN_TABLE[[#This Row],[Date]], "mmm") -> Apr | N7: =YEAR(CLEAN_TABLE[[#This Row],[Date]]) -> 2024 | O7: =IF(CLEAN_TABLE[[#This Row],[Farmer_Type]]="Smart",0,1) -> 0 | P7: =IFERROR(CLEAN_TABLE[[#This Row],[Savings]]/CLEAN_TABLE[[#This Row],[Income]],0) -> 0.60968033 | Q7: =IF(CLEAN_TABLE[[#This Row],[Farmer_Type]]="Smart", 1 - (CLEAN_TABLE[[#This Row],[Irrigation]] / 70), 1 - (CLEAN_TABLE[[#This Row],[Irrigation]] / 150)) -> 0.77342857 | R7: =_xlfn.LET( _xlpm.income,CLEAN_TABLE[[#This Row],[Income]], _xlpm.expense,CLEAN_TABLE[[#This Row],[TotalExpenses]], _xlpm.saving,CLEAN_TABLE[[#This Row],[Savings]], IF(_xlpm.saving < 0, 20, IF(_xlpm.saving/_xlpm.income < 0.1, 40, IF(_xlpm.saving/_xlpm.income < 0.2, 60, 80)))) -> 80 | S7: =CLEAN_TABLE[[#This Row],[Income]]+CLEAN_TABLE[[#This Row],[Irrigation]]+CLEAN_TABLE[[#This Row],[Seeds ]]+CLEAN_TABLE[[#This Row],[Fertilizer]]+CLEAN_TABLE[[#This Row],[Labour ]]+CLEAN_TABLE[[#This Row],[Household]]+CLEAN_TABLE[[#This Row],[Medical ]]+CLEAN_TABLE[[#This Row],[Misc]] -> 1526.16
A8: =FARM_DATA[[#This Row],[Date]] -> 45389 | B8: =FARM_DATA[[#This Row],[Farmer_Type]] -> Smart | C8: =FARM_DATA[[#This Row],[Income]] -> 1018.72 | D8: =FARM_DATA[[#This Row],[Irrigation]] -> 6.18 | E8: =FARM_DATA[[#This Row],[Seeds]] -> 66.48 | F8: =FARM_DATA[[#This Row],[Fertilizer]] -> 68.45 | G8: =FARM_DATA[[#This Row],[Labor]] -> 81.46 | H8: =FARM_DATA[[#This Row],[Household]] -> 191.41 | I8: =FARM_DATA[[#This Row],[Medical]] -> 31.28 | J8: =FARM_DATA[[#This Row],[Misc]] -> 53.97 | K8: =FARM_DATA[[#This Row],[Total_Expenses]] -> 499.23 | L8: =FARM_DATA[[#This Row],[Savings]] -> 519.49 | M8: =TEXT(CLEAN_TABLE[[#This Row],[Date]], "mmm") -> Apr | N8: =YEAR(CLEAN_TABLE[[#This Row],[Date]]) -> 2024 | O8: =IF(CLEAN_TABLE[[#This Row],[Farmer_Type]]="Smart",0,1) -> 0 | P8: =IFERROR(CLEAN_TABLE[[#This Row],[Savings]]/CLEAN_TABLE[[#This Row],[Income]],0) -> 0.50994385 | Q8: =IF(CLEAN_TABLE[[#This Row],[Farmer_Type]]="Smart", 1 - (CLEAN_TABLE[[#This Row],[Irrigation]] / 70), 1 - (CLEAN_TABLE[[#This Row],[Irrigation]] / 150)) -> 0.91171429 | R8: =_xlfn.LET( _xlpm.income,CLEAN_TABLE[[#This Row],[Income]], _xlpm.expense,CLEAN_TABLE[[#This Row],[TotalExpenses]], _xlpm.saving,CLEAN_TABLE[[#This Row],[Savings]], IF(_xlpm.saving < 0, 20, IF(_xlpm.saving/_xlpm.income < 0.1, 40, IF(_xlpm.saving/_xlpm.income < 0.2, 60, 80)))) -> 80 | S8: =CLEAN_TABLE[[#This Row],[Income]]+CLEAN_TABLE[[#This Row],[Irrigation]]+CLEAN_TABLE[[#This Row],[Seeds ]]+CLEAN_TABLE[[#This Row],[Fertilizer]]+CLEAN_TABLE[[#This Row],[Labour ]]+CLEAN_TABLE[[#This Row],[Household]]+CLEAN_TABLE[[#This Row],[Medical ]]+CLEAN_TABLE[[#This Row],[Misc]] -> 1517.95
A9: =FARM_DATA[[#This Row],[Date]] -> 45390 | B9: =FARM_DATA[[#This Row],[Farmer_Type]] -> Traditional | C9: =FARM_DATA[[#This Row],[Income]] -> 308.04 | D9: =FARM_DATA[[#This Row],[Irrigation]] -> 66.91 | E9: =FARM_DATA[[#This Row],[Seeds]] -> 44.97 | F9: =FARM_DATA[[#This Row],[Fertilizer]] -> 74.51 | G9: =FARM_DATA[[#This Row],[Labor]] -> 98.02 | H9: =FARM_DATA[[#This Row],[Household]] -> 144.43 | I9: =FARM_DATA[[#This Row],[Medical]] -> 11.15 | J9: =FARM_DATA[[#This Row],[Misc]] -> 15.65 | K9: =FARM_DATA[[#This Row],[Total_Expenses]] -> 455.63 | L9: =FARM_DATA[[#This Row],[Savings]] -> -147.59 | M9: =TEXT(CLEAN_TABLE[[#This Row],[Date]], "mmm") -> Apr | N9: =YEAR(CLEAN_TABLE[[#This Row],[Date]]) -> 2024 | O9: =IF(CLEAN_TABLE[[#This Row],[Farmer_Type]]="Smart",0,1) -> 1 | P9: =IFERROR(CLEAN_TABLE[[#This Row],[Savings]]/CLEAN_TABLE[[#This Row],[Income]],0) -> -0.47912609 | Q9: =IF(CLEAN_TABLE[[#This Row],[Farmer_Type]]="Smart", 1 - (CLEAN_TABLE[[#This Row],[Irrigation]] / 70), 1 - (CLEAN_TABLE[[#This Row],[Irrigation]] / 150)) -> 0.55393333 | R9: =_xlfn.LET( _xlpm.income,CLEAN_TABLE[[#This Row],[Income]], _xlpm.expense,CLEAN_TABLE[[#This Row],[TotalExpenses]], _xlpm.saving,CLEAN_TABLE[[#This Row],[Savings]], IF(_xlpm.saving < 0, 20, IF(_xlpm.saving/_xlpm.income < 0.1, 40, IF(_xlpm.saving/_xlpm.income < 0.2, 60, 80)))) -> 20 | S9: =CLEAN_TABLE[[#This Row],[Income]]+CLEAN_TABLE[[#This Row],[Irrigation]]+CLEAN_TABLE[[#This Row],[Seeds ]]+CLEAN_TABLE[[#This Row],[Fertilizer]]+CLEAN_TABLE[[#This Row],[Labour ]]+CLEAN_TABLE[[#This Row],[Household]]+CLEAN_TABLE[[#This Row],[Medical ]]+CLEAN_TABLE[[#This Row],[Misc]] -> 763.68
A10: =FARM_DATA[[#This Row],[Date]] -> 45391 | B10: =FARM_DATA[[#This Row],[Farmer_Type]] -> Traditional | C10: =FARM_DATA[[#This Row],[Income]] -> 390.63 | D10: =FARM_DATA[[#This Row],[Irrigation]] -> 83.56 | E10: =FARM_DATA[[#This Row],[Seeds]] -> 38.92 | F10: =FARM_DATA[[#This Row],[Fertilizer]] -> 75.07 | G10: =FARM_DATA[[#This Row],[Labor]] -> 119.04 | H10: =FARM_DATA[[#This Row],[Household]] -> 130.65 | I10: =FARM_DATA[[#This Row],[Medical]] -> 22.89 | J10: =FARM_DATA[[#This Row],[Misc]] -> 48.46 | K10: =FARM_DATA[[#This Row],[Total_Expenses]] -> 518.59 | L10: =FARM_DATA[[#This Row],[Savings]] -> -127.96 | M10: =TEXT(CLEAN_TABLE[[#This Row],[Date]], "mmm") -> Apr | N10: =YEAR(CLEAN_TABLE[[#This Row],[Date]]) -> 2024 | O10: =IF(CLEAN_TABLE[[#This Row],[Farmer_Type]]="Smart",0,1) -> 1 | P10: =IFERROR(CLEAN_TABLE[[#This Row],[Savings]]/CLEAN_TABLE[[#This Row],[Income]],0) -> -0.32757341 | Q10: =IF(CLEAN_TABLE[[#This Row],[Farmer_Type]]="Smart", 1 - (CLEAN_TABLE[[#This Row],[Irrigation]] / 70), 1 - (CLEAN_TABLE[[#This Row],[Irrigation]] / 150)) -> 0.44293333 | R10: =_xlfn.LET( _xlpm.income,CLEAN_TABLE[[#This Row],[Income]], _xlpm.expense,CLEAN_TABLE[[#This Row],[TotalExpenses]], _xlpm.saving,CLEAN_TABLE[[#This Row],[Savings]], IF(_xlpm.saving < 0, 20, IF(_xlpm.saving/_xlpm.income < 0.1, 40, IF(_xlpm.saving/_xlpm.income < 0.2, 60, 80)))) -> 20 | S10: =CLEAN_TABLE[[#This Row],[Income]]+CLEAN_TABLE[[#This Row],[Irrigation]]+CLEAN_TABLE[[#This Row],[Seeds ]]+CLEAN_TABLE[[#This Row],[Fertilizer]]+CLEAN_TABLE[[#This Row],[Labour ]]+CLEAN_TABLE[[#This Row],[Household]]+CLEAN_TABLE[[#This Row],[Medical ]]+CLEAN_TABLE[[#This Row],[Misc]] -> 909.22
A11: =FARM_DATA[[#This Row],[Date]] -> 45392 | B11: =FARM_DATA[[#This Row],[Farmer_Type]] -> Traditional | C11: =FARM_DATA[[#This Row],[Income]] -> 348.21 | D11: =FARM_DATA[[#This Row],[Irrigation]] -> 85.65 | E11: =FARM_DATA[[#This Row],[Seeds]] -> 0.7 | F11: =FARM_DATA[[#This Row],[Fertilizer]] -> 71.44 | G11: =FARM_DATA[[#This Row],[Labor]] -> 112.18 | H11: =FARM_DATA[[#This Row],[Household]] -> 141.03 | I11: =FARM_DATA[[#This Row],[Medical]] -> 20.73 | J11: =FARM_DATA[[#This Row],[Misc]] -> 6.15 | K11: =FARM_DATA[[#This Row],[Total_Expenses]] -> 437.88 | L11: =FARM_DATA[[#This Row],[Savings]] -> -89.67 | M11: =TEXT(CLEAN_TABLE[[#This Row],[Date]], "mmm") -> Apr | N11: =YEAR(CLEAN_TABLE[[#This Row],[Date]]) -> 2024 | O11: =IF(CLEAN_TABLE[[#This Row],[Farmer_Type]]="Smart",0,1) -> 1 | P11: =IFERROR(CLEAN_TABLE[[#This Row],[Savings]]/CLEAN_TABLE[[#This Row],[Income]],0) -> -0.25751702 | Q11: =IF(CLEAN_TABLE[[#This Row],[Farmer_Type]]="Smart", 1 - (CLEAN_TABLE[[#This Row],[Irrigation]] / 70), 1 - (CLEAN_TABLE[[#This Row],[Irrigation]] / 150)) -> 0.429 | R11: =_xlfn.LET( _xlpm.income,CLEAN_TABLE[[#This Row],[Income]], _xlpm.expense,CLEAN_TABLE[[#This Row],[TotalExpenses]], _xlpm.saving,CLEAN_TABLE[[#This Row],[Savings]], IF(_xlpm.saving < 0, 20, IF(_xlpm.saving/_xlpm.income < 0.1, 40, IF(_xlpm.saving/_xlpm.income < 0.2, 60, 80)))) -> 20 | S11: =CLEAN_TABLE[[#This Row],[Income]]+CLEAN_TABLE[[#This Row],[Irrigation]]+CLEAN_TABLE[[#This Row],[Seeds ]]+CLEAN_TABLE[[#This Row],[Fertilizer]]+CLEAN_TABLE[[#This Row],[Labour ]]+CLEAN_TABLE[[#This Row],[Household]]+CLEAN_TABLE[[#This Row],[Medical ]]+CLEAN_TABLE[[#This Row],[Misc]] -> 786.09
A12: =FARM_DATA[[#This Row],[Date]] -> 45393 | B12: =FARM_DATA[[#This Row],[Farmer_Type]] -> Smart | C12: =FARM_DATA[[#This Row],[Income]] -> 906.07 | D12: =FARM_DATA[[#This Row],[Irrigation]] -> 16.79 | E12: =FARM_DATA[[#This Row],[Seeds]] -> 89.56 | F12: =FARM_DATA[[#This Row],[Fertilizer]] -> 64.45 | G12: =FARM_DATA[[#This Row],[Labor]] -> 78.83 | H12: =FARM_DATA[[#This Row],[Household]] -> 152.44 | I12: =FARM_DATA[[#This Row],[Medical]] -> 30.24 | J12: =FARM_DATA[[#This Row],[Misc]] -> 44.93 | K12: =FARM_DATA[[#This Row],[Total_Expenses]] -> 477.23 | L12: =FARM_DATA[[#This Row],[Savings]] -> 428.83 | M12: =TEXT(CLEAN_TABLE[[#This Row],[Date]], "mmm") -> Apr | N12: =YEAR(CLEAN_TABLE[[#This Row],[Date]]) -> 2024 | O12: =IF(CLEAN_TABLE[[#This Row],[Farmer_Type]]="Smart",0,1) -> 0 | P12: =IFERROR(CLEAN_TABLE[[#This Row],[Savings]]/CLEAN_TABLE[[#This Row],[Income]],0) -> 0.47328573 | Q12: =IF(CLEAN_TABLE[[#This Row],[Farmer_Type]]="Smart", 1 - (CLEAN_TABLE[[#This Row],[Irrigation]] / 70), 1 - (CLEAN_TABLE[[#This Row],[Irrigation]] / 150)) -> 0.76014286 | R12: =_xlfn.LET( _xlpm.income,CLEAN_TABLE[[#This Row],[Income]], _xlpm.expense,CLEAN_TABLE[[#This Row],[TotalExpenses]], _xlpm.saving,CLEAN_TABLE[[#This Row],[Savings]], IF(_xlpm.saving < 0, 20, IF(_xlpm.saving/_xlpm.income < 0.1, 40, IF(_xlpm.saving/_xlpm.income < 0.2, 60, 80)))) -> 80 | S12: =CLEAN_TABLE[[#This Row],[Income]]+CLEAN_TABLE[[#This Row],[Irrigation]]+CLEAN_TABLE[[#This Row],[Seeds ]]+CLEAN_TABLE[[#This Row],[Fertilizer]]+CLEAN_TABLE[[#This Row],[Labour ]]+CLEAN_TABLE[[#This Row],[Household]]+CLEAN_TABLE[[#This Row],[Medical ]]+CLEAN_TABLE[[#This Row],[Misc]] -> 1383.31
A13: =FARM_DATA[[#This Row],[Date]] -> 45394 | B13: =FARM_DATA[[#This Row],[Farmer_Type]] -> Smart | C13: =FARM_DATA[[#This Row],[Income]] -> 844.05 | D13: =FARM_DATA[[#This Row],[Irrigation]] -> 17.57 | E13: =FARM_DATA[[#This Row],[Seeds]] -> 61.94 | F13: =FARM_DATA[[#This Row],[Fertilizer]] -> 109.06 | G13: =FARM_DATA[[#This Row],[Labor]] -> 80.96 | H13: =FARM_DATA[[#This Row],[Household]] -> 158.53 | I13: =FARM_DATA[[#This Row],[Medical]] -> 18.47 | J13: =FARM_DATA[[#This Row],[Misc]] -> 18.05 | K13: =FARM_DATA[[#This Row],[Total_Expenses]] -> 464.58 | L13: =FARM_DATA[[#This Row],[Savings]] -> 379.47 | M13: =TEXT(CLEAN_TABLE[[#This Row],[Date]], "mmm") -> Apr | N13: =YEAR(CLEAN_TABLE[[#This Row],[Date]]) -> 2024 | O13: =IF(CLEAN_TABLE[[#This Row],[Farmer_Type]]="Smart",0,1) -> 0 | P13: =IFERROR(CLEAN_TABLE[[#This Row],[Savings]]/CLEAN_TABLE[[#This Row],[Income]],0) -> 0.44958237 | Q13: =IF(CLEAN_TABLE[[#This Row],[Farmer_Type]]="Smart", 1 - (CLEAN_TABLE[[#This Row],[Irrigation]] / 70), 1 - (CLEAN_TABLE[[#This Row],[Irrigation]] / 150)) -> 0.749 | R13: =_xlfn.LET( _xlpm.income,CLEAN_TABLE[[#This Row],[Income]], _xlpm.expense,CLEAN_TABLE[[#This Row],[TotalExpenses]], _xlpm.saving,CLEAN_TABLE[[#This Row],[Savings]], IF(_xlpm.saving < 0, 20, IF(_xlpm.saving/_xlpm.income < 0.1, 40, IF(_xlpm.saving/_xlpm.income < 0.2, 60, 80)))) -> 80 | S13: =CLEAN_TABLE[[#This Row],[Income]]+CLEAN_TABLE[[#This Row],[Irrigation]]+CLEAN_TABLE[[#This Row],[Seeds ]]+CLEAN_TABLE[[#This Row],[Fertilizer]]+CLEAN_TABLE[[#This Row],[Labour ]]+CLEAN_TABLE[[#This Row],[Household]]+CLEAN_TABLE[[#This Row],[Medical ]]+CLEAN_TABLE[[#This Row],[Misc]] -> 1308.63
... A366: =FARM_DATA[[#This Row],[Date]] -> 45747 | B366: =FARM_DATA[[#This Row],[Farmer_Type]] -> Traditional | C366: =FARM_DATA[[#This Row],[Income]] -> 313.45 | D366: =FARM_DATA[[#This Row],[Irrigation]] -> 77.58 | E366: =FARM_DATA[[#This Row],[Seeds]] -> 50.28 | F366: =FARM_DATA[[#This Row],[Fertilizer]] -> 91.97 | G366: =FARM_DATA[[#This Row],[Labor]] -> 105.61 | H366: =FARM_DATA[[#This Row],[Household]] -> 170.06 | I366: =FARM_DATA[[#This Row],[Medical]] -> 20.78 | J366: =FARM_DATA[[#This Row],[Misc]] -> 45.55 | K366: =FARM_DATA[[#This Row],[Total_Expenses]] -> 561.84 | L366: =FARM_DATA[[#This Row],[Savings]] -> -248.39 | M366: =TEXT(CLEAN_TABLE[[#This Row],[Date]], "mmm") -> Mar | N366: =YEAR(CLEAN_TABLE[[#This Row],[Date]]) -> 2025 | O366: =IF(CLEAN_TABLE[[#This Row],[Farmer_Type]]="Smart",0,1) -> 1 | P366: =IFERROR(CLEAN_TABLE[[#This Row],[Savings]]/CLEAN_TABLE[[#This Row],[Income]],0) -> -0.79243899 | Q366: =IF(CLEAN_TABLE[[#This Row],[Farmer_Type]]="Smart", 1 - (CLEAN_TABLE[[#This Row],[Irrigation]] / 70), 1 - (CLEAN_TABLE[[#This Row],[Irrigation]] / 150)) -> 0.4828 | R366: =_xlfn.LET( _xlpm.income,CLEAN_TABLE[[#This Row],[Income]], _xlpm.expense,CLEAN_TABLE[[#This Row],[TotalExpenses]], _xlpm.saving,CLEAN_TABLE[[#This Row],[Savings]], IF(_xlpm.saving < 0, 20, IF(_xlpm.saving/_xlpm.income < 0.1, 40, IF(_xlpm.saving/_xlpm.income < 0.2, 60, 80)))) -> 20 | S366: =CLEAN_TABLE[[#This Row],[Income]]+CLEAN_TABLE[[#This Row],[Irrigation]]+CLEAN_TABLE[[#This Row],[Seeds ]]+CLEAN_TABLE[[#This Row],[Fertilizer]]+CLEAN_TABLE[[#This Row],[Labour ]]+CLEAN_TABLE[[#This Row],[Household]]+CLEAN_TABLE[[#This Row],[Medical ]]+CLEAN_TABLE[[#This Row],[Misc]] -> 875.28

Sheet PROJECTION 
A1: Month_End | B1: Total_Income | C1: TotalExpenses | D1: Total_Savings | E1: Savings_Rate | F1: Avg_Risk_Scores | G1: Traditional_Savings | H1: Smart_Savings
A2: {=_xlfn.UNIQUE(CLEAN_DATA!M2:M366)} -> Apr | B2: {=SUMIFS(CLEAN_DATA!C2:C366,CLEAN_DATA!M2:M366,_xlfn.ANCHORARRAY('PROJECTION '!A2))} -> 17972.31 | C2: {=SUMIFS(CLEAN_DATA!K2:K366,CLEAN_DATA!M2:M366,_xlfn.ANCHORARRAY('PROJECTION '!A2))} -> 14265.21 | D2: {=SUMIFS(CLEAN_DATA!L2:L366,CLEAN_DATA!M2:M366,_xlfn.ANCHORARRAY('PROJECTION '!A2))} -> 3707.04 | E2: {=IFERROR(_xlfn.ANCHORARRAY(D2)/_xlfn.ANCHORARRAY(B2),0)} -> 0.20626397 | F2: {=AVERAGEIFS(CLEAN_DATA!R2:R366,CLEAN_DATA!M2:M366,_xlfn.ANCHORARRAY('PROJECTION '!A2))} -> 46 | G2: {=SUMIFS(CLEAN_TABLE[Savings],CLEAN_TABLE[Month],_xlfn.ANCHORARRAY('PROJECTION '!A2),CLEAN_TABLE[Farmer_Type],"Traditional")} -> -2272.04 | H2: {=SUMIFS(CLEAN_TABLE[Savings],CLEAN_TABLE[Month],_xlfn.ANCHORARRAY('PROJECTION '!A2),CLEAN_TABLE[Farmer_Type],"Smart")} -> 5979.08
A3: May | B3: 18313.29 | C3: 14694.68 | D3: 3618.59 | E3: 0.19759366 | F3: 41.290323 | G3: -2509.79 | H3: 6128.38
A4: Jun | B4: 19232.72 | C4: 14272.81 | D4: 4959.9 | E4: 0.25788864 | F4: 49.333333 | G4: -1710.54 | H4: 6670.44
A5: Jul | B5: 19605.4 | C5: 15242.26 | D5: 4363.16 | E5: 0.22254889 | F5: 50.967742 | G5: -2228.38 | H5: 6591.54
A6: Aug | B6: 20464.31 | C6: 15289.65 | D6: 5174.64 | E6: 0.25286169 | F6: 49.032258 | G6: -1953.4 | H6: 7128.04
A7: Sep | B7: 18106.58 | C7: 14739.78 | D7: 3366.83 | E7: 0.18594511 | F7: 44 | G7: -2358.51 | H7: 5725.34
A8: Oct | B8: 20450.91 | C8: 15229.2 | D8: 5221.68 | E8: 0.25532751 | F8: 50.967742 | G8: -2006.24 | H8: 7227.92
A9: Nov | B9: 20309.44 | C9: 14348.61 | D9: 5960.87 | E9: 0.29350243 | F9: 50 | G9: -1996.58 | H9: 7957.45
A10: Dec | B10: 20320.51 | C10: 14720.56 | D10: 5599.93 | E10: 0.27558019 | F10: 50.967742 | G10: -1388.81 | H10: 6988.74
A11: Jan | B11: 19083.3 | C11: 14938.42 | D11: 4144.91 | E11: 0.2172009 | F11: 46.451613 | G11: -2511.08 | H11: 6655.99
A12: Feb | B12: 18347.33 | C12: 13467.36 | D12: 4879.99 | E12: 0.26597821 | F12: 52.142857 | G12: -1186.67 | H12: 6066.66
A13: Mar | B13: 19233.98 | C13: 14868.86 | D13: 4365.12 | E13: 0.22694835 | F13: 48.387097 | G13: -2610.12 | H13: 6975.24
E15: =AVERAGE(_xlfn.ANCHORARRAY(E2)) -> 0.23813663
D17: Monthly Income vs Expenses
A18: Row Labels | B18: Sum of Total_Income | C18: Sum of TotalExpenses
A19: Jan | B19: 19083.3 | C19: 14938.42
A20: Feb | B20: 18347.33 | C20: 13467.36
A21: Mar | B21: 19233.98 | C21: 14868.86
A22: Apr | B22: 17972.31 | C22: 14265.21
A23: May | B23: 18313.29 | C23: 14694.68
A24: Jun | B24: 19232.72 | C24: 14272.81
A25: Jul | B25: 19605.4 | C25: 15242.26
A26: Aug | B26: 20464.31 | C26: 15289.65
A27: Sep | B27: 18106.58 | C27: 14739.78
A28: Oct | B28: 20450.91 | C28: 15229.2
A29: Nov | B29: 20309.44 | C29: 14348.61
A30: Dec | B30: 20320.51 | C30: 14720.56
A31: Grand Total | B31: 231440.08 | C31: 176077.4
D33: Savings Trend (12-Month Projection)
A34: Row Labels | B34: Sum of Total_Savings
A35: Jan | B35: 4144.91
A36: Feb | B36: 4879.99
A37: Mar | B37: 4365.12
A38: Apr | B38: 3707.04
A39: May | B39: 3618.59
A40: Jun | B40: 4959.9
A41: Jul | B41: 4363.16
A42: Aug | B42: 5174.64
A43: Sep | B43: 3366.83
...

Sheet Dashboard

Sheet Sheet7

Sheet Pivot Tables and Charts
A2: Monthly Income vs Monthly Expenses
A3: Row Labels | B3: Sum of TotalExpenses | C3: Sum of Total_Income
A4: Jan | B4: 14938.42 | C4: 19083.3
A5: Feb | B5: 13467.36 | C5: 18347.33
A6: Mar | B6: 14868.86 | C6: 19233.98
A7: Apr | B7: 4942.6 | C7: 5315.48
A8: May | B8: 14694.68 | C8: 18313.29
A9: Jun | B9: 14272.81 | C9: 19232.72
A10: Jul | B10: 15242.26 | C10: 19605.4
A11: Aug | B11: 15289.65 | C11: 20464.31
A12: Sep | B12: 14739.78 | C12: 18106.58
A13: Oct | B13: 15229.2 | C13: 20450.91
A14: Nov | B14: 14348.61 | C14: 20309.44
A15: Dec | B15: 14720.56 | C15: 20320.51
A16: Grand Total | B16: 166754.79 | C16: 218783.25
A20: Month_End | B20: Total_Savings
A21: {=_xlfn.UNIQUE(CLEAN_DATA!M21:M385)} -> Apr | B21: {=SUMIFS(CLEAN_DATA!J21:J385,CLEAN_DATA!K21:K385,_xlfn.ANCHORARRAY('PROJECTION '!#REF!))} -> 0
A22: May
A23: Jun
A24: Jul
A25: Aug
A26: Sep
A27: Oct
A28: Nov
A29: Dec
A30: Jan
A31: Feb
A32: Mar
A33: 0
